  <?xml version="1.0" ?>
  <!-- =================================================================================== -->
  <!-- |    This document was autogenerated by xacro from ./urdf.xacro                   | -->
  <!-- |    EDITING THIS FILE BY HAND IS NOT RECOMMENDED                                 | -->
  <!-- =================================================================================== -->
  <robot name="sawyer">
    <material name="black">
      <color rgba="0 0 0 1"/>
    </material>
    <material name="darkgray">
      <color rgba=".2 .2 .2 1"/>
    </material>
    <material name="darkred">
      <color rgba=".5 .1 .1 1"/>
    </material>
    <material name="sawyer_red">
      <color rgba=".5 .1 .1 1"/>
    </material>
    <material name="sawyer_gray">
      <color rgba="0.75294 0.75294 0.75294 1"/>
    </material>
    <!-- base -->
    <link name="base">
  	  </link>
    <!-- torso -->
    <link name="torso">
      <visual>
        <origin rpy="0 0 0" xyz="0 0 0"/>
        <geometry>
          <box size="0 0 0"/>
        </geometry>
        <material name="darkgray">
          <color rgba=".2 .2 .2 1"/>
        </material>
      </visual>
      <inertial>
        <origin rpy="0 0 0" xyz="0.000000 0.000000 0.000000"/>
        <mass value="0.0001"/>
        <inertia ixx="1e-08" ixy="0" ixz="0" iyy="1e-08" iyz="0" izz="1e-08"/>
      </inertial>
    </link>
    <!-- pedestal -->
    <link name="pedestal">
      <visual>
        <origin rpy="1.57079632679 0 -1.57079632679" xyz="0.26 0.345 -0.91488"/>
        <geometry>
          <mesh filename="package://sawyer_description/meshes/sawyer_pv/pedestal.DAE"/>
        </geometry>
        <material name="darkgray"/>
      </visual>
      <collision>
        <origin rpy="0 0 0" xyz="0 0 -0.30"/>
        <geometry>
          <cylinder length="0.62" radius="0.18"/>
        </geometry>
      </collision>
      <inertial>
        <origin rpy="0 0 0" xyz="0 0 0"/>
        <mass value="60.86397744"/>
        <inertia ixx="5.0635929" ixy="0.00103417" ixz="0.80199628" iyy="6.08689388" iyz="0.00105311" izz="4.96191932"/>
      </inertial>
    </link>
    <!--  Joints -->
    <!--  Torso -->
    <joint name="torso_t0" type="fixed">
      <origin rpy="0 0 0" xyz="0 0 0"/>
      <parent link="base"/>
      <child link="torso"/>
      <limit effort="50000" lower="-3.01" upper="3.01" velocity="10000"/>
    </joint>
    <!-- pedestal -->
    <joint name="pedestal_fixed" type="fixed">
      <origin rpy="0 0 0" xyz="0.0 0.0 0.0"/>
      <parent link="base"/>
      <child link="pedestal"/>
    </joint>
    <!--
         UNITS:
         mass:      kg
         distances: m
         rotations: rads
         inertias:  kg-m2
        -->
    <joint name="right_arm_mount" type="fixed">
      <origin rpy="0 0 0" xyz="0.0 0.0 0.0"/>
      <parent link="base"/>
      <child link="right_arm_base_link"/>
    </joint>
    <link name="right_arm_base_link">
      <inertial>
        <origin rpy="0 0 0" xyz="5.8473E-05 -0.00029673 0.066717"/>
        <mass value="2.0406"/>
        <inertia ixx="0.0066411" ixy="-9.9986E-06" ixz="-5.2017E-05" iyy="0.0065701" iyz="2.7844E-05" izz="0.0070835"/>
      </inertial>
      <visual>
        <origin rpy="0 0 0" xyz="0 0 0"/>
        <geometry>
          <mesh filename="package://sawyer_description/meshes/sawyer_pv/base.DAE"/>
        </geometry>
        <material name="sawyer_red"/>
      </visual>
      <collision>
        <origin rpy="0 0 0" xyz="0 0 0.12"/>
        <geometry>
          <cylinder length="0.24" radius="0.08"/>
        </geometry>
      </collision>
    </link>
    <link name="right_l0">
      <inertial>
        <origin rpy="0 0 0" xyz="0.026897 0.015562 0.14742"/>
        <mass value="5.4419"/>
        <inertia ixx="0.056423" ixy="0.0059481" ixz="0.013001" iyy="0.06" iyz="0.010005" izz="0.025707"/>
      </inertial>
      <visual>
        <origin rpy="0 0 0" xyz="0 0 0"/>
        <geometry>
          <mesh filename="package://sawyer_description/meshes/sawyer_pv/l0.DAE"/>
        </geometry>
        <material name="sawyer_red"/>
      </visual>
      <collision>
        <origin rpy="0 0 0" xyz="0.081 0 0.237"/>
        <geometry>
          <sphere radius="0.07"/>
        </geometry>
      </collision>
    </link>
    <joint name="right_j0" type="revolute">
      <origin rpy="0 0 0" xyz="0 0 0.08"/>
      <parent link="right_arm_base_link"/>
      <child link="right_l0"/>
      <axis xyz="0 0 1"/>
      <limit effort="80.0" lower="-3.0503" upper="3.0503" velocity="1.48"/>
    </joint>
    <link name="head">
      <inertial>
        <origin rpy="0 0 0" xyz="0.0055105 -1.3557E-05 0.10079"/>
        <mass value="1.5614"/>
        <inertia ixx="0.011575" ixy="-5.8549E-07" ixz="0.00010303" iyy="0.0080118" iyz="3.1652E-07" izz="0.0049374"/>
      </inertial>
      <visual>
        <origin rpy="0 0 0" xyz="0 0 0"/>
        <geometry>
          <mesh filename="package://sawyer_description/meshes/sawyer_pv/head.DAE"/>
        </geometry>
        <material name="sawyer_red"/>
      </visual>
      <collision>
        <origin rpy="0 0 0" xyz="0 0 0.08"/>
        <geometry>
          <sphere radius="0.18"/>
        </geometry>
      </collision>
    </link>
    <joint name="head_pan" type="revolute">
      <origin rpy="0 0 0" xyz="0 0 0.2965"/>
      <parent link="right_l0"/>
      <child link="head"/>
      <axis xyz="0 0 1"/>
      <limit effort="8" lower="-5.1477" upper="0.9559" velocity="1.8"/>
    </joint>
    <!-- origin is center of knob on backside of pcb -->
    <link name="right_torso_itb">
      <!-- note: invisible -->
      <inertial>
        <origin rpy="0 0 0" xyz="0.000000 0.000000 0.000000"/>
        <mass value="0.0001"/>
        <inertia ixx="1e-08" ixy="0" ixz="0" iyy="1e-08" iyz="0" izz="1e-08"/>
      </inertial>
    </link>
    <joint name="right_torso_itb" type="fixed">
      <origin rpy="0 -1.57079632679 0" xyz="-.055 0 .22"/>
      <parent link="right_l0"/>
      <child link="right_torso_itb"/>
      <axis xyz="0 0 1"/>
    </joint>
    <link name="right_l1">
      <inertial>
        <origin rpy="0 0 0" xyz="-0.0049064 -0.025872 0.090315"/>
        <mass value="4.6966"/>
        <inertia ixx="0.021073" ixy="-0.00034243" ixz="-0.0005556" iyy="0.013367" iyz="-0.0051674" izz="0.017659"/>
      </inertial>
      <visual>
        <origin rpy="0 0 0" xyz="0 0 0"/>
        <geometry>
          <mesh filename="package://sawyer_description/meshes/sawyer_pv/l1.DAE"/>
        </geometry>
        <material name="sawyer_red"/>
      </visual>
      <collision>
        <origin rpy="0 0 0" xyz="0 0 0.1225"/>
        <geometry>
          <sphere radius="0.07"/>
        </geometry>
      </collision>
    </link>
    <joint name="right_j1" type="revolute">
      <origin rpy="-1.57079632679 1.57079632679 0" xyz="0.081 0.06 0.237"/>
      <parent link="right_l0"/>
      <child link="right_l1"/>
      <axis xyz="0 0 1"/>
      <limit effort="80.0" lower="-3.8183" upper="2.2824" velocity="1.13"/>
    </joint>
    <link name="right_l2">
      <inertial>
        <origin rpy="0 0 0" xyz="5.506E-05 -0.016031 0.13283"/>
        <mass value="1.5828"/>
        <inertia ixx="0.024751" ixy="1.116E-05" ixz="4.6629E-06" iyy="0.024426" iyz="-0.0033227" izz="0.003068"/>
      </inertial>
      <visual>
        <origin rpy="0 0 0" xyz="0 0 0"/>
        <geometry>
          <mesh filename="package://sawyer_description/meshes/sawyer_pv/l2.DAE"/>
        </geometry>
        <material name="sawyer_red"/>
      </visual>
      <collision>
        <origin rpy="0 0 0" xyz="0 0 0.14"/>
        <geometry>
          <cylinder length="0.35" radius="0.06"/>
        </geometry>
      </collision>
    </link>
    <joint name="right_j2" type="revolute">
      <origin rpy="1.57079632679 0 0" xyz="0 -0.14 0.1325"/>
      <parent link="right_l1"/>
      <child link="right_l2"/>
      <axis xyz="0 0 1"/>
      <limit effort="40.0" lower="-3.0514" upper="3.0514" velocity="1.66"/>
    </joint>
    <link name="right_l3">
      <inertial>
        <origin rpy="0 0 0" xyz="-0.0046678 -0.028394 -0.083127"/>
        <mass value="2.4383"/>
        <inertia ixx="0.0097448" ixy="-1.0855E-05" ixz="0.00026017" iyy="0.0062616" iyz="0.0030278" izz="0.0066963"/>
      </inertial>
      <visual>
        <origin rpy="0 0 0" xyz="0 0 0"/>
        <geometry>
          <mesh filename="package://sawyer_description/meshes/sawyer_pv/l3.DAE"/>
        </geometry>
        <material name="sawyer_red"/>
      </visual>
      <collision>
        <origin rpy="0 0 0" xyz="0 -0.01 -0.12"/>
        <geometry>
          <sphere radius="0.06"/>
        </geometry>
      </collision>
    </link>
    <joint name="right_j3" type="revolute">
      <origin rpy="-1.57079632679 0 0" xyz="0 -0.042 0.26"/>
      <parent link="right_l2"/>
      <child link="right_l3"/>
      <axis xyz="0 0 1"/>
      <limit effort="40.0" lower="-3.0514" upper="3.0514" velocity="1.66"/>
    </joint>
    <link name="right_l4">
      <inertial>
        <origin rpy="0 0 0" xyz="-0.0019515 0.0080422 0.13745"/>
        <mass value="0.9418"/>
        <inertia ixx="0.012433" ixy="1.7679E-05" ixz="0.00012176" iyy="0.012478" iyz="0.0010824" izz="0.0011594"/>
      </inertial>
      <visual>
        <origin rpy="0 0 0" xyz="0 0 0"/>
        <geometry>
          <mesh filename="package://sawyer_description/meshes/sawyer_pv/l4.DAE"/>
        </geometry>
        <material name="sawyer_red"/>
      </visual>
      <collision>
        <origin rpy="0 0 0" xyz="0 0 0.14"/>
        <geometry>
          <cylinder length="0.36" radius="0.045"/>
        </geometry>
      </collision>
    </link>
    <joint name="right_j4" type="revolute">
      <origin rpy="1.57079632679 0 0" xyz="0 -0.125 -0.1265"/>
      <parent link="right_l3"/>
      <child link="right_l4"/>
      <axis xyz="0 0 1"/>
      <limit effort="9.0" lower="-2.9842" upper="2.9842" velocity="2.96"/>
    </joint>
    <!-- origin is center of knob on backside of pcb -->
    <link name="right_arm_itb">
      <!-- note: invisible -->
      <inertial>
        <origin rpy="0 0 0" xyz="0.000000 0.000000 0.000000"/>
        <mass value="0.0001"/>
        <inertia ixx="1e-08" ixy="0" ixz="0" iyy="1e-08" iyz="0" izz="1e-08"/>
      </inertial>
    </link>
    <joint name="right_arm_itb" type="fixed">
      <origin rpy="0 -1.57079632679 0" xyz="-.055 0 .075"/>
      <parent link="right_l4"/>
      <child link="right_arm_itb"/>
      <axis xyz="0 0 1"/>
    </joint>
    <link name="right_l5">
      <inertial>
        <origin rpy="0 0 0" xyz="0.0057826 -0.024546 0.075192"/>
        <mass value="1.4915"/>
        <inertia ixx="0.0045548" ixy="0.00011036" ixz="4.6698E-05" iyy="0.0028212" iyz="-0.0011798" izz="0.003056"/>
      </inertial>
      <visual>
        <origin rpy="0 0 0" xyz="0 0 0"/>
        <geometry>
          <mesh filename="package://sawyer_description/meshes/sawyer_pv/l5.DAE"/>
        </geometry>
        <material name="sawyer_red"/>
      </visual>
      <collision>
        <origin rpy="0 0 0" xyz="0.01 0 0.09"/>
        <geometry>
          <sphere radius="0.06"/>
        </geometry>
      </collision>
    </link>
    <joint name="right_j5" type="revolute">
      <origin rpy="-1.57079632679 0 0" xyz="0 0.031 0.275"/>
      <parent link="right_l4"/>
      <child link="right_l5"/>
      <axis xyz="0 0 1"/>
      <limit effort="9.0" lower="-2.9842" upper="2.9842" velocity="2.96"/>
    </joint>
    <link name="right_hand_camera"/>
    <joint name="right_hand_camera" type="fixed">
      <origin rpy="0 1.57079632679 0" xyz="0.019552 -0.033 0.0695"/>
      <parent link="right_l5"/>
      <child link="right_hand_camera"/>
      <axis xyz="0 0 0"/>
    </joint>
    <link name="right_wrist"/>
    <joint name="right_wrist" type="fixed">
      <origin rpy="1.57079632679 0 0" xyz="0 0 0.10541"/>
      <parent link="right_l5"/>
      <child link="right_wrist"/>
      <axis xyz="0 0 0"/>
    </joint>
    <link name="right_l6">
      <inertial>
        <origin rpy="0 0 0" xyz="-0.00010735 0.0090388 0.0018977"/>
        <mass value="0.32204"/>
        <inertia ixx="0.00030221" ixy="4.1981E-07" ixz="-2.0185E-07" iyy="0.00020857" iyz="-9.1363E-06" izz="0.00035146"/>
      </inertial>
      <visual>
        <origin rpy="0 0 0" xyz="0 0 0"/>
        <geometry>
          <mesh filename="package://sawyer_description/meshes/sawyer_pv/l6.DAE"/>
        </geometry>
        <material name="sawyer_red"/>
      </visual>
      <collision>
        <origin rpy="0 0 0" xyz="0 0 -0.005"/>
        <geometry>
          <cylinder length="0.05" radius="0.065"/>
        </geometry>
      </collision>
    </link>
    <joint name="right_j6" type="revolute">
      <origin rpy="1.57079632679 3.31612 0" xyz="0 -0.1098 0.1053"/>
      <parent link="right_l5"/>
      <child link="right_l6"/>
      <axis xyz="0 0 1"/>
      <limit effort="9.0" lower="-4.7104" upper="4.7104" velocity="3.86"/>
    </joint>
    <link name="right_hand">
      <collision>
        <origin rpy="0 0 0" xyz="0 0 0.02"/>
        <geometry>
          <cylinder length="0.04" radius="0.06"/>
        </geometry>
      </collision>
      <inertial>
        <origin rpy="0 0 0" xyz="0.01093 0.00042 -0.01532"/>
        <mass value="0.19125"/>
        <inertia ixx="0.00017588" ixy="0.00000147073" ixz="0.0000243633" iyy="0.00021166377" iyz="0.00000172689" izz="0.00023745397"/>
      </inertial>
    </link>
    <joint name="right_hand" type="fixed">
      <origin rpy="0 0 1.570796" xyz="0 0 0.02285"/>
      <axis xyz="0 0 1"/>
      <parent link="right_l6"/>
      <child link="right_hand"/>
    </joint>
    <link name="screen">
      <visual>
        <origin rpy="0 0 0" xyz="0 0 0"/>
        <geometry>
          <box size="0.24 0.14 0.002"/>
        </geometry>
        <material name="darkgray"/>
      </visual>
      <collision>
        <origin rpy="0 0 0" xyz="0 0 0"/>
        <geometry>
          <sphere radius="0.001"/>
        </geometry>
      </collision>
      <inertial>
        <origin rpy="0 0 0" xyz="0 0 0"/>
        <mass value="0.0001"/>
        <inertia ixx="1e-08" ixy="0" ixz="0" iyy="1e-08" iyz="0" izz="1e-08"/>
      </inertial>
    </link>
    <joint name="display_joint" type="fixed">
      <origin rpy="1.57079632679 0 1.57079632679" xyz="0.03 0.0 0.105"/>
      <parent link="head"/>
      <child link="screen"/>
    </joint>
    <link name="head_camera"/>
    <joint name="head_camera" type="fixed">
      <origin rpy="-2.1293 0 -1.57079632679" xyz="0.015925 0 0.22087"/>
      <parent link="head"/>
      <child link="head_camera"/>
      <axis xyz="0 0 0"/>
    </joint>
  </robot>
  
  
